[2023-08-14T06:09:45.743+0000] {taskinstance.py:1083} INFO - Dependencies all met for <TaskInstance: data_dag.fail scheduled__2023-08-09T00:00:00+00:00 [queued]>
[2023-08-14T06:09:45.755+0000] {taskinstance.py:1083} INFO - Dependencies all met for <TaskInstance: data_dag.fail scheduled__2023-08-09T00:00:00+00:00 [queued]>
[2023-08-14T06:09:45.755+0000] {taskinstance.py:1279} INFO - 
--------------------------------------------------------------------------------
[2023-08-14T06:09:45.756+0000] {taskinstance.py:1280} INFO - Starting attempt 1 of 1
[2023-08-14T06:09:45.756+0000] {taskinstance.py:1281} INFO - 
--------------------------------------------------------------------------------
[2023-08-14T06:09:45.775+0000] {taskinstance.py:1300} INFO - Executing <Task(BashOperator): fail> on 2023-08-09 00:00:00+00:00
[2023-08-14T06:09:45.780+0000] {standard_task_runner.py:55} INFO - Started process 2259 to run task
[2023-08-14T06:09:45.783+0000] {standard_task_runner.py:82} INFO - Running: ['***', 'tasks', 'run', 'data_dag', 'fail', 'scheduled__2023-08-09T00:00:00+00:00', '--job-id', '16', '--raw', '--subdir', 'DAGS_FOLDER/data_dag.py', '--cfg-path', '/tmp/tmp69q262ku']
[2023-08-14T06:09:45.783+0000] {standard_task_runner.py:83} INFO - Job 16: Subtask fail
[2023-08-14T06:09:45.798+0000] {warnings.py:110} WARNING - /home/***/.local/lib/python3.7/site-packages/***/settings.py:400: DeprecationWarning: The sql_engine_encoding option in [core] has been moved to the sql_engine_encoding option in [database] - the old setting has been used, but please update your config.
  engine_args["encoding"] = conf.get("database", "SQL_ENGINE_ENCODING", fallback="utf-8")

[2023-08-14T06:09:45.853+0000] {task_command.py:388} INFO - Running <TaskInstance: data_dag.fail scheduled__2023-08-09T00:00:00+00:00 [running]> on host 7dfb041806a2
[2023-08-14T06:09:45.939+0000] {taskinstance.py:1509} INFO - Exporting the following env vars:
AIRFLOW_CTX_DAG_OWNER=***
AIRFLOW_CTX_DAG_ID=data_dag
AIRFLOW_CTX_TASK_ID=fail
AIRFLOW_CTX_EXECUTION_DATE=2023-08-09T00:00:00+00:00
AIRFLOW_CTX_TRY_NUMBER=1
AIRFLOW_CTX_DAG_RUN_ID=scheduled__2023-08-09T00:00:00+00:00
[2023-08-14T06:09:45.941+0000] {subprocess.py:63} INFO - Tmp dir root location: 
 /tmp
[2023-08-14T06:09:45.941+0000] {subprocess.py:75} INFO - Running command: ['/bin/bash', '-c', '\n                valid=09\n                if [ $(($valid % 2)) == 1 ]; then\n                        exit 1\n                else\n                        exit 0\n                fi\n            ']
[2023-08-14T06:09:45.951+0000] {subprocess.py:86} INFO - Output:
[2023-08-14T06:09:45.953+0000] {subprocess.py:93} INFO - /bin/bash: line 3: 09: value too great for base (error token is "09")
[2023-08-14T06:09:45.953+0000] {subprocess.py:97} INFO - Command exited with return code 1
[2023-08-14T06:09:45.964+0000] {taskinstance.py:1768} ERROR - Task failed with exception
Traceback (most recent call last):
  File "/home/airflow/.local/lib/python3.7/site-packages/airflow/operators/bash.py", line 197, in execute
    f"Bash command failed. The command returned a non-zero exit code {result.exit_code}."
airflow.exceptions.AirflowException: Bash command failed. The command returned a non-zero exit code 1.
[2023-08-14T06:09:45.969+0000] {taskinstance.py:1323} INFO - Marking task as FAILED. dag_id=data_dag, task_id=fail, execution_date=20230809T000000, start_date=20230814T060945, end_date=20230814T060945
[2023-08-14T06:09:45.984+0000] {standard_task_runner.py:105} ERROR - Failed to execute job 16 for task fail (Bash command failed. The command returned a non-zero exit code 1.; 2259)
[2023-08-14T06:09:45.995+0000] {local_task_job.py:208} INFO - Task exited with return code 1
[2023-08-14T06:09:46.014+0000] {taskinstance.py:2578} INFO - 0 downstream tasks scheduled from follow-on schedule check
